<!DOCTYPE HTML PUBLIC "-//W3C//DTD HTML 3.2//EN">
<HTML>
 <HEAD>
   <TITLE> [Twisted-Python] how to write a safe catch-all
   </TITLE>
   <LINK REL="Index" HREF="index.html" >
   <LINK REL="made" HREF="mailto:twisted-python%40twistedmatrix.com?Subject=%5BTwisted-Python%5D%20how%20to%20write%20a%20safe%20catch-all&In-Reply-To=4CA361A5.2090005%40simplistix.co.uk">
   <META NAME="robots" CONTENT="index,nofollow">
   <META http-equiv="Content-Type" content="text/html; charset=us-ascii">
   <LINK REL="Previous"  HREF="022935.html">
   <LINK REL="Next"  HREF="022937.html">
 </HEAD>
 <BODY BGCOLOR="#ffffff">
   <H1>[Twisted-Python] how to write a safe catch-all</H1>
    <B>Phil Mayers</B> 
    <A HREF="mailto:twisted-python%40twistedmatrix.com?Subject=%5BTwisted-Python%5D%20how%20to%20write%20a%20safe%20catch-all&In-Reply-To=4CA361A5.2090005%40simplistix.co.uk"
       TITLE="[Twisted-Python] how to write a safe catch-all">p.mayers at imperial.ac.uk
       </A><BR>
    <I>Wed Sep 29 12:16:53 EDT 2010</I>
    <P><UL>
        <LI>Previous message: <A HREF="022935.html">[Twisted-Python] how to write a safe catch-all
</A></li>
        <LI>Next message: <A HREF="022937.html">[Twisted-Python] how to write a safe catch-all
</A></li>
         <LI> <B>Messages sorted by:</B> 
              <a href="date.html#22936">[ date ]</a>
              <a href="thread.html#22936">[ thread ]</a>
              <a href="subject.html#22936">[ subject ]</a>
              <a href="author.html#22936">[ author ]</a>
         </LI>
       </UL>
    <HR>  
<!--beginarticle-->
<PRE>On 29/09/10 16:56, Chris Withers wrote:
&gt;<i> On 28/09/2010 15:21, <A HREF="http://twistedmatrix.com/cgi-bin/mailman/listinfo/twisted-python">exarkun at twistedmatrix.com</A> wrote:
</I>&gt;&gt;&gt;<i> But, more crucially, the looping call then appears to stop.
</I>&gt;&gt;<i>
</I>&gt;&gt;<i> The function you're looping over returns a Deferred that never fires.
</I>&gt;&gt;<i> The LoopingCall isn't stopped, it's waiting for the Deferred.
</I>&gt;<i>
</I>&gt;<i> So, inlineCallbacks/generator things will only process errbacks, not
</I>&gt;<i> actual exceptions raised inside asyncronous code called from them?!
</I>
No.

The problem is that your example is malformed. You do this:

  1. Create a deferred on the &quot;Break&quot; class instance
  2. Return it from doStuff
  3. You &quot;callLater&quot; doesn't touch that deferred, so the 
generator/doStuff call a) never calls back and b) discards any errors 
that happen inside callLater.

You want something like this:

class Break:

     def __init__(self):
         self.deferred = Deferred()

     def __call__(self):
         try:
             del self.connector
         except:
             self.deferred.errback()
         else:
             self.deferred.callback(1)


</PRE>




<!--endarticle-->
    <HR>
    <P><UL>
        <!--threads-->
	<LI>Previous message: <A HREF="022935.html">[Twisted-Python] how to write a safe catch-all
</A></li>
	<LI>Next message: <A HREF="022937.html">[Twisted-Python] how to write a safe catch-all
</A></li>
         <LI> <B>Messages sorted by:</B> 
              <a href="date.html#22936">[ date ]</a>
              <a href="thread.html#22936">[ thread ]</a>
              <a href="subject.html#22936">[ subject ]</a>
              <a href="author.html#22936">[ author ]</a>
         </LI>
       </UL>

<hr>
<a href="http://twistedmatrix.com/cgi-bin/mailman/listinfo/twisted-python">More information about the Twisted-Python
mailing list</a><br>
</body></html>
