<!DOCTYPE HTML PUBLIC "-//W3C//DTD HTML 3.2//EN">
<HTML>
 <HEAD>
   <TITLE> [Twisted-Python] exceptions in adbapi
   </TITLE>
   <LINK REL="Index" HREF="index.html" >
   <LINK REL="made" HREF="mailto:twisted-python%40twistedmatrix.com?Subject=%5BTwisted-Python%5D%20exceptions%20in%20adbapi&In-Reply-To=F92274058556DE42B94B148EEFB9183949E777%40exchange-03.suedkurier.de">
   <META NAME="robots" CONTENT="index,nofollow">
   <META http-equiv="Content-Type" content="text/html; charset=us-ascii">
   <LINK REL="Previous"  HREF="010959.html">
   <LINK REL="Next"  HREF="010962.html">
 </HEAD>
 <BODY BGCOLOR="#ffffff">
   <H1>[Twisted-Python] exceptions in adbapi</H1>
    <B>Dave Peticolas</B> 
    <A HREF="mailto:twisted-python%40twistedmatrix.com?Subject=%5BTwisted-Python%5D%20exceptions%20in%20adbapi&In-Reply-To=F92274058556DE42B94B148EEFB9183949E777%40exchange-03.suedkurier.de"
       TITLE="[Twisted-Python] exceptions in adbapi">dave at krondo.com
       </A><BR>
    <I>Mon Jul 11 21:45:58 EDT 2005</I>
    <P><UL>
        <LI>Previous message: <A HREF="010959.html">[Twisted-Python] exceptions in adbapi
</A></li>
        <LI>Next message: <A HREF="010962.html">[Twisted-Python] Understanding the IOCP reactor and adding	spawnProcess
</A></li>
         <LI> <B>Messages sorted by:</B> 
              <a href="date.html#10974">[ date ]</a>
              <a href="thread.html#10974">[ thread ]</a>
              <a href="subject.html#10974">[ subject ]</a>
              <a href="author.html#10974">[ author ]</a>
         </LI>
       </UL>
    <HR>  
<!--beginarticle-->
<PRE>On Mon, 2005-07-11 at 16:07 +0200, <A HREF="http://twistedmatrix.com/cgi-bin/mailman/listinfo/twisted-python">Henning.Ramm at mediapro-gmbh.de</A> wrote:
&gt;<i> Hi there!
</I>&gt;<i> 
</I>&gt;<i> I've a twisted app as database proxy server that handles all database queries for my other apps (via a pb connection).
</I>&gt;<i> Now I get thousands of exceptions that I can't trace back, two kind:
</I>&gt;<i> 
</I>&gt;<i> 2005-07-11 15:57:36,707	defer.328	[ERROR]
</I>&gt;<i> [Failure instance: Traceback: _mysql_exceptions.Warning: Datens&#228;tze gefunden: 1  Ge&#228;ndert: 0  Warnungen: 1
</I>&gt;<i> D:\Python\lib\threading.py:422:run
</I>&gt;<i> D:\Python\lib\site-packages\twisted\python\threadpool.py:145:_worker
</I>&gt;<i> D:\Python\lib\site-packages\twisted\python\context.py:52:callWithContext
</I>&gt;<i> D:\Python\lib\site-packages\twisted\python\context.py:31:callWithContext
</I>&gt;<i> --- &lt;exception caught here&gt; ---
</I>&gt;<i> D:\Python\lib\site-packages\twisted\internet\threads.py:25:_putResultInDeferred
</I>&gt;<i> D:\Python\lib\site-packages\twisted\enterprise\adbapi.py:302:_runInteraction
</I>&gt;<i> D:\Python\lib\site-packages\twisted\enterprise\adbapi.py:311:_runQuery
</I>&gt;<i> D:\Python\lib\site-packages\MySQLdb\cursors.py:95:execute
</I>&gt;<i> D:\Python\lib\site-packages\MySQLdb\cursors.py:114:_execute
</I>&gt;<i> D:\Python\lib\site-packages\MySQLdb\connections.py:33:defaulterrorhandler
</I>&gt;<i> ]
</I>&gt;<i> 2005-07-11 15:57:36,707	defer.328	[ERROR]
</I>&gt;<i> [Failure instance: Traceback: _mysql_exceptions.IntegrityError: (1062, &quot;Doppelter Eintrag 'TA_V_23_130705' f\xfcr Schl\xfcssel 1.&quot;)
</I>&gt;<i> D:\Python\lib\threading.py:422:run
</I>&gt;<i> D:\Python\lib\site-packages\twisted\python\threadpool.py:145:_worker
</I>&gt;<i> D:\Python\lib\site-packages\twisted\python\context.py:52:callWithContext
</I>&gt;<i> D:\Python\lib\site-packages\twisted\python\context.py:31:callWithContext
</I>&gt;<i> --- &lt;exception caught here&gt; ---
</I>&gt;<i> D:\Python\lib\site-packages\twisted\internet\threads.py:25:_putResultInDeferred
</I>&gt;<i> D:\Python\lib\site-packages\twisted\enterprise\adbapi.py:302:_runInteraction
</I>&gt;<i> D:\Python\lib\site-packages\twisted\enterprise\adbapi.py:311:_runQuery
</I>&gt;<i> D:\Python\lib\site-packages\MySQLdb\cursors.py:95:execute
</I>&gt;<i> D:\Python\lib\site-packages\MySQLdb\cursors.py:114:_execute
</I>&gt;<i> D:\Python\lib\site-packages\MySQLdb\connections.py:33:defaulterrorhandler
</I>&gt;<i> ]
</I>&gt;<i> 
</I>&gt;<i> The first one is absolutely useless - MySQL tells me only that it could process the query (&quot;datasets found: 1, changed 0, warning: 1&quot;); I'd like to block that completely.
</I>&gt;<i> 
</I>&gt;<i> The second one means that I tried an insert with an existing key (&quot;Double entry '...' for key 1&quot;); also no problem, if I could handle it and do an update query instead.
</I>&gt;<i> 
</I>&gt;<i> But as you can see, I can't trace the messages back to one of my methods (and I have already every function call in a try..except clause).
</I>&gt;<i> 
</I>&gt;<i> Any hints?
</I>
These exceptions are happening in your Deferred callbacks. You need to
attach an error handler (the asynchronous counterpart to an except: 
clause) to the deferred you get back as a result of your adbapi call.

See twisted.internet.defer for more details.

dave




</PRE>

<!--endarticle-->
    <HR>
    <P><UL>
        <!--threads-->
	<LI>Previous message: <A HREF="010959.html">[Twisted-Python] exceptions in adbapi
</A></li>
	<LI>Next message: <A HREF="010962.html">[Twisted-Python] Understanding the IOCP reactor and adding	spawnProcess
</A></li>
         <LI> <B>Messages sorted by:</B> 
              <a href="date.html#10974">[ date ]</a>
              <a href="thread.html#10974">[ thread ]</a>
              <a href="subject.html#10974">[ subject ]</a>
              <a href="author.html#10974">[ author ]</a>
         </LI>
       </UL>

<hr>
<a href="http://twistedmatrix.com/cgi-bin/mailman/listinfo/twisted-python">More information about the Twisted-Python
mailing list</a><br>
</body></html>
