<tt>
I&nbsp;have&nbsp;a&nbsp;PB&nbsp;server,&nbsp;and&nbsp;one&nbsp;of&nbsp;my&nbsp;clients&nbsp;keeps&nbsp;getting&nbsp;this&nbsp;error:&lt;br&gt;&lt;br&gt;Traceback&nbsp;(most&nbsp;recent&nbsp;call&nbsp;last):&lt;br&gt;&nbsp;&nbsp;File&nbsp;&quot;C:\Python24\Lib\site-packages\twisted\python\log.py&quot;,&nbsp;line&nbsp;53,&nbsp;in&nbsp;callWithLogger&lt;br&gt;&nbsp;&nbsp;&nbsp;&nbsp;return&nbsp;callWithContext({&quot;system&quot;:&nbsp;lp},&nbsp;func,&nbsp;*args,&nbsp;**kw)<br>
&lt;br&gt;&nbsp;&nbsp;File&nbsp;&quot;C:\Python24\Lib\site-packages\twisted\python\log.py&quot;,&nbsp;line&nbsp;38,&nbsp;in&nbsp;callWithContext&lt;br&gt;&nbsp;&nbsp;&nbsp;&nbsp;return&nbsp;context.call({ILogContext:&nbsp;newCtx},&nbsp;func,&nbsp;*args,&nbsp;**kw)&lt;br&gt;&nbsp;&nbsp;File&nbsp;&quot;C:\Python24\Lib\site-packages\twisted\python\context.py&quot;,&nbsp;line&nbsp;59,&nbsp;in&nbsp;callWithContext<br>
&lt;br&gt;&nbsp;&nbsp;&nbsp;&nbsp;return&nbsp;self.currentContext().callWithContext(ctx,&nbsp;func,&nbsp;*args,&nbsp;**kw)&lt;br&gt;&nbsp;&nbsp;File&nbsp;&quot;C:\Python24\Lib\site-packages\twisted\python\context.py&quot;,&nbsp;line&nbsp;37,&nbsp;in&nbsp;callWithContext&lt;br&gt;&nbsp;&nbsp;&nbsp;&nbsp;return&nbsp;func(*args,**kw)&lt;br&gt;---&nbsp;&lt;exception&nbsp;caught&nbsp;here&gt;&nbsp;---<br>
&lt;br&gt;&nbsp;&nbsp;File&nbsp;&quot;C:\Python24\Lib\site-packages\twisted\internet\selectreactor.py&quot;,&nbsp;line&nbsp;139,&nbsp;in&nbsp;_doReadOrWrite&lt;br&gt;&nbsp;&nbsp;&nbsp;&nbsp;why&nbsp;=&nbsp;getattr(selectable,&nbsp;method)()&lt;br&gt;&nbsp;&nbsp;File&nbsp;&quot;C:\Python24\Lib\site-packages\twisted\internet\tcp.py&quot;,&nbsp;line&nbsp;348,&nbsp;in&nbsp;doRead<br>
&lt;br&gt;&nbsp;&nbsp;&nbsp;&nbsp;return&nbsp;self.protocol.dataReceived(data)&lt;br&gt;&nbsp;&nbsp;File&nbsp;&quot;C:\Python24\Lib\site-packages\twisted\spread\banana.py&quot;,&nbsp;line&nbsp;184,&nbsp;in&nbsp;dataReceived&lt;br&gt;&nbsp;&nbsp;&nbsp;&nbsp;gotItem(item)&lt;br&gt;&nbsp;&nbsp;File&nbsp;&quot;C:\Python24\Lib\site-packages\twisted\spread\banana.py&quot;,&nbsp;line&nbsp;114,&nbsp;in&nbsp;gotItem<br>
&lt;br&gt;&nbsp;&nbsp;&nbsp;&nbsp;self.callExpressionReceived(item)&lt;br&gt;&nbsp;&nbsp;File&nbsp;&quot;C:\Python24\Lib\site-packages\twisted\spread\banana.py&quot;,&nbsp;line&nbsp;81,&nbsp;in&nbsp;callExpressionReceived&lt;br&gt;&nbsp;&nbsp;&nbsp;&nbsp;self.expressionReceived(obj)&lt;br&gt;&nbsp;&nbsp;File&nbsp;&quot;C:\Python24\Lib\site-packages\twisted\spread\pb.py&quot;,&nbsp;line&nbsp;559,&nbsp;in&nbsp;expressionReceived<br>
&lt;br&gt;&nbsp;&nbsp;&nbsp;&nbsp;method(*sexp[1:])&lt;br&gt;&nbsp;&nbsp;File&nbsp;&quot;C:\Python24\Lib\site-packages\twisted\spread\pb.py&quot;,&nbsp;line&nbsp;926,&nbsp;in&nbsp;proto_answer&lt;br&gt;&nbsp;&nbsp;&nbsp;&nbsp;d&nbsp;=&nbsp;self.waitingForAnswers[requestID]&lt;br&gt;exceptions.KeyError:&nbsp;113&lt;br&gt;connection&nbsp;lost,&nbsp;reason&nbsp;&lt;<br>
twisted.python.failure.Failure&nbsp;exceptions.KeyError&gt;&lt;br&gt;&lt;br&gt;Note&nbsp;that&nbsp;the&nbsp;server&nbsp;and&nbsp;client&nbsp;are&nbsp;on&nbsp;the&nbsp;same&nbsp;machine.&nbsp;The&nbsp;client&nbsp;is&nbsp;reading&nbsp;log&nbsp;files&nbsp;and&nbsp;sending&nbsp;certain&nbsp;lines&nbsp;to&nbsp;the&nbsp;PB&nbsp;server.&nbsp;This&nbsp;is&nbsp;fairly&nbsp;high&nbsp;volume,&nbsp;and&nbsp;when&nbsp;it&nbsp;seems&nbsp;to&nbsp;peak&nbsp;this&nbsp;happens.&nbsp;<br>
&lt;br&gt;&lt;br&gt;I'm&nbsp;also&nbsp;using&nbsp;a&nbsp;ReconnectingPBClientFactory,&nbsp;but&nbsp;it&nbsp;doesn't&nbsp;reconnect&nbsp;when&nbsp;this&nbsp;error&nbsp;occures.&lt;br&gt;&lt;br&gt;Any&nbsp;ideas&nbsp;out&nbsp;there?&lt;br&gt;&lt;br&gt;Thanks,&lt;br&gt;&lt;br&gt;Don&lt;br&gt;<br>

</tt>
