<!DOCTYPE HTML PUBLIC "-//W3C//DTD HTML 4.01 Transitional//EN">
<HTML>
 <HEAD>
   <TITLE> [Twisted-Python] problems with tracebacks
   </TITLE>
   <LINK REL="Index" HREF="index.html" >
   <LINK REL="made" HREF="mailto:twisted-python%40twistedmatrix.com?Subject=Re%3A%20%5BTwisted-Python%5D%20problems%20with%20tracebacks&In-Reply-To=%3C44D3B910.9080507%40libero.it%3E">
   <META NAME="robots" CONTENT="index,nofollow">
   <style type="text/css">
       pre {
           white-space: pre-wrap;       /* css-2.1, curent FF, Opera, Safari */
           }
   </style>
   <META http-equiv="Content-Type" content="text/html; charset=utf-8">
   <LINK REL="Previous"  HREF="046280.html">
   <LINK REL="Next"  HREF="046282.html">
 </HEAD>
 <BODY BGCOLOR="#ffffff">
   <H1>[Twisted-Python] problems with tracebacks</H1>
    <B>Manlio Perillo</B> 
    <A HREF="mailto:twisted-python%40twistedmatrix.com?Subject=Re%3A%20%5BTwisted-Python%5D%20problems%20with%20tracebacks&In-Reply-To=%3C44D3B910.9080507%40libero.it%3E"
       TITLE="[Twisted-Python] problems with tracebacks">manlio_perillo at libero.it
       </A><BR>
    <I>Fri Aug  4 15:16:00 MDT 2006</I>
    <P><UL>
        <LI>Previous message (by thread): <A HREF="046280.html">[Twisted-Python] problems with tracebacks
</A></li>
        <LI>Next message (by thread): <A HREF="046282.html">[Twisted-Python] problems with tracebacks
</A></li>
         <LI> <B>Messages sorted by:</B> 
              <a href="date.html#46281">[ date ]</a>
              <a href="thread.html#46281">[ thread ]</a>
              <a href="subject.html#46281">[ subject ]</a>
              <a href="author.html#46281">[ author ]</a>
         </LI>
       </UL>
    <HR>  
<!--beginarticle-->
<PRE>Christopher Armstrong ha scritto:
&gt;<i> On 8/4/06, *Manlio Perillo* &lt;<A HREF="https://twistedmatrix.com/cgi-bin/mailman/listinfo/twisted-python">manlio_perillo at libero.it</A>
</I>&gt;<i> &lt;mailto:<A HREF="https://twistedmatrix.com/cgi-bin/mailman/listinfo/twisted-python">manlio_perillo at libero.it</A>&gt;&gt; wrote:
</I>&gt;<i> 
</I>&gt;<i>     This problem seems to happen from time in time.
</I>&gt;<i> 
</I>&gt;<i>     Traceback are not printed.
</I>&gt;<i> 
</I>&gt;<i>     Now I'm running trial on a test case and I got:
</I>&gt;<i> 
</I>&gt;<i>     [...]
</I>&gt;<i>     test.test_mail.TestMail.test_email_plain ... [OK]
</I>&gt;<i>     test.test_mail.TestMail.test_sendmail_html ... [ERROR]
</I>&gt;<i>     test.test_mail.TestMail.test_sendmail_text ... [ERROR]
</I>&gt;<i> 
</I>&gt;<i>     ===============================================================================
</I>&gt;<i>     [ERROR]: test.test_mail.TestMail.test_sendmail_html
</I>&gt;<i> 
</I>&gt;<i>     Failure: exceptions.IndexError: list index out of range
</I>&gt;<i>     ===============================================================================
</I>&gt;<i>     [ERROR]: test.test_mail.TestMail.test_sendmail_text
</I>&gt;<i> 
</I>&gt;<i>     Failure: twisted.internet.defer.TimeoutError : &lt;test.test_mail.TestMail
</I>&gt;<i>     testMetho
</I>&gt;<i>     d=test_sendmail_text&gt; (test_sendmail_text) still running at 3.0 secs
</I>&gt;<i>     -------------------------------------------------------------------------------
</I>&gt;<i>     Ran 4 tests in 3.078s
</I>&gt;<i> 
</I>&gt;<i>     FAILED (errors=2, successes=1)
</I>&gt;<i> 
</I>&gt;<i>  
</I>&gt;<i> 
</I>&gt;<i>     Unfortunately every time I got this problem I'm unable to write a small
</I>&gt;<i>     reproducible code.
</I>&gt;<i>     And every time the problem is caused by a simple bug in the code.
</I>&gt;<i> 
</I>&gt;<i> 
</I>&gt;<i> 
</I>&gt;<i> What are your test cases subclassing? What version of Twisted are you using?
</I>&gt;<i>  
</I>


I use this simple test case:

class TestMail(unittest.TestCase):
    &quot;&quot;&quot;Test sendmail function

    XXX TODO: do not use a real mail server!
              see twisted.mail.test.test_mail
    &quot;&quot;&quot;

    timeout = 10

    def tearDownClass(self):
        # XXX TODO tearDown the resolver
        pass

    def test_senmail(self):
        text = u&quot;Test&quot;

        msg = mail.MIMEText(text)
        # ...

        mail.sendmail(msg)



The sendmail function is:

def sendmail(email):
    &quot;&quot;&quot;Send an email message.
    &quot;&quot;&quot;

    def gotMX(mx):
        return smtp.sendmail(mx, from_, [to], msg)


    try:
        # some things that can fail
        # (and *do* fail: do I just got another email package bug?)
	# ...

        msg = flatten(email)
    except Exception, reason:
        return defer.fail(reason)

    mxc = getMX()
    return mxc.getMX(host).addCallback(lambda mx: gotMX(str(mx.name)))



The problem seems to be with the try statement.
When I try to print or log.err the exception, I don't get the full
traceback.



Thanks and regards  Manlio Perillo


</PRE>

<!--endarticle-->
    <HR>
    <P><UL>
        <!--threads-->
	<LI>Previous message (by thread): <A HREF="046280.html">[Twisted-Python] problems with tracebacks
</A></li>
	<LI>Next message (by thread): <A HREF="046282.html">[Twisted-Python] problems with tracebacks
</A></li>
         <LI> <B>Messages sorted by:</B> 
              <a href="date.html#46281">[ date ]</a>
              <a href="thread.html#46281">[ thread ]</a>
              <a href="subject.html#46281">[ subject ]</a>
              <a href="author.html#46281">[ author ]</a>
         </LI>
       </UL>

<hr>
<a href="https://twistedmatrix.com/cgi-bin/mailman/listinfo/twisted-python">More information about the Twisted-Python
mailing list</a><br>
</body></html>
